<?xml version="1.0" ?>
<!--
SPDX-FileCopyrightText: 2025, FANUC America Corporation
SPDX-FileCopyrightText: 2025, FANUC CORPORATION
SPDX-License-Identifier: Apache-2.0
-->
<!-- URDF for LR Mate 7/7D (LR Mate 200iD) -->
<robot xmlns:xacro="http://wiki.ros.org/xacro">
  <xacro:macro
    name="lrmate200id"
    params="prefix=''
            parent
            *origin
            child"
  >

    <xacro:property name="j1_lower_limit" value="${radians(-170)}" />
    <xacro:property name="j2_lower_limit" value="${radians(-100)}" />
    <xacro:property name="j3_lower_limit" value="${radians(-70)}" />
    <xacro:property name="j4_lower_limit" value="${radians(-190)}" />
    <xacro:property name="j5_lower_limit" value="${radians(-125)}" />
    <xacro:property name="j6_lower_limit" value="${radians(-360)}" />

    <xacro:property name="j1_upper_limit" value="${radians( 170)}" />
    <xacro:property name="j2_upper_limit" value="${radians( 145)}" />
    <xacro:property name="j3_upper_limit" value="${radians( 205)}" />
    <xacro:property name="j4_upper_limit" value="${radians( 190)}" />
    <xacro:property name="j5_upper_limit" value="${radians( 125)}" />
    <xacro:property name="j6_upper_limit" value="${radians( 360)}" />

    <xacro:property name="j1_effort_limit" value=" 450" />
    <xacro:property name="j2_effort_limit" value=" 500" />
    <xacro:property name="j3_effort_limit" value=" 200" />
    <xacro:property name="j4_effort_limit" value=" 70" />
    <xacro:property name="j5_effort_limit" value=" 40" />
    <xacro:property name="j6_effort_limit" value=" 20" />

    <xacro:property name="j1_velocity_limit" value="${radians( 450)}" />
    <xacro:property name="j2_velocity_limit" value="${radians( 380)}" />
    <xacro:property name="j3_velocity_limit" value="${radians( 520)}" />
    <xacro:property name="j4_velocity_limit" value="${radians( 550)}" />
    <xacro:property name="j5_velocity_limit" value="${radians( 545)}" />
    <xacro:property name="j6_velocity_limit" value="${radians( 1000)}" />

    <!-- links -->
    <link name="${prefix}base_link">
      <visual>
        <origin xyz="0 0 0" rpy="0 0 0" />
        <geometry>
          <mesh
            filename="package://fanuc_lrmate_description/meshes/lrmate200id/visual/base.dae"
          />
        </geometry>
      </visual>
      <collision>
        <origin xyz="0 0 0" rpy="0 0 0" />
        <geometry>
          <mesh
            filename="package://fanuc_lrmate_description/meshes/lrmate200id/collision/base.stl"
            scale="0.001 0.001 0.001"
          />
        </geometry>
      </collision>
      <inertial>
        <mass value=" 8" />
        <origin xyz="-.02 -.01  .1" />
        <inertia
          ixx=" 0"
          ixy=" 0"
          ixz=" 0"
          iyy=" 0"
          iyz=" 0"
          izz=" 0"
        />
      </inertial>
    </link>

    <link name="${prefix}J1_link">
      <visual>
        <origin xyz="0 0 0" rpy="0 0 0" />
        <geometry>
          <mesh
            filename="package://fanuc_lrmate_description/meshes/lrmate200id/visual/j1.dae"
          />
        </geometry>
      </visual>
      <collision>
        <origin xyz="0 0 0" rpy="0 0 0" />
        <geometry>
          <mesh
            filename="package://fanuc_lrmate_description/meshes/lrmate200id/collision/j1.stl"
            scale="0.001 0.001 0.001"
          />
        </geometry>
      </collision>
      <inertial>
        <mass value=" 4" />
        <origin xyz=" .03  .03 -.05" />
        <inertia
          ixx=" 0"
          ixy=" 0"
          ixz=" 0"
          iyy=" 0"
          iyz=" 0"
          izz=" 0"
        />
      </inertial>
    </link>

    <link name="${prefix}J2_link">
      <visual>
        <origin xyz="0 0 0" rpy="0 0 0" />
        <geometry>
          <mesh
            filename="package://fanuc_lrmate_description/meshes/lrmate200id/visual/j2.dae"
          />
        </geometry>
      </visual>
      <collision>
        <origin xyz="0 0 0" rpy="0 0 0" />
        <geometry>
          <mesh
            filename="package://fanuc_lrmate_description/meshes/lrmate200id/collision/j2.stl"
            scale="0.001 0.001 0.001"
          />
        </geometry>
      </collision>
      <inertial>
        <mass value=" 6" />
        <origin xyz="-.01  .01  .1" />
        <inertia
          ixx=" .1"
          ixy=" 0"
          ixz=" 0"
          iyy=" .1"
          iyz=" 0"
          izz=" 0"
        />
      </inertial>
    </link>

    <link name="${prefix}J3_link">
      <visual>
        <origin xyz="0 0 0" rpy="0 0 0" />
        <geometry>
          <mesh
            filename="package://fanuc_lrmate_description/meshes/lrmate200id/visual/j3.dae"
          />
        </geometry>
      </visual>
      <collision>
        <origin xyz="0 0 0" rpy="0 0 0" />
        <geometry>
          <mesh
            filename="package://fanuc_lrmate_description/meshes/lrmate200id/collision/j3.stl"
            scale="0.001 0.001 0.001"
          />
        </geometry>
      </collision>
      <inertial>
        <mass value=" 2" />
        <origin xyz=" .01  .01  .01" />
        <inertia
          ixx=" 0"
          ixy=" 0"
          ixz=" 0"
          iyy=" 0"
          iyz=" 0"
          izz=" 0"
        />
      </inertial>
    </link>

    <link name="${prefix}J4_link">
      <visual>
        <origin xyz="0 0 0" rpy="0 0 0" />
        <geometry>
          <mesh
            filename="package://fanuc_lrmate_description/meshes/lrmate200id/visual/j4.dae"
          />
        </geometry>
      </visual>
      <collision>
        <origin xyz="0 0 0" rpy="0 0 0" />
        <geometry>
          <mesh
            filename="package://fanuc_lrmate_description/meshes/lrmate200id/collision/j4.stl"
            scale="0.001 0.001 0.001"
          />
        </geometry>
      </collision>
      <inertial>
        <mass value=" 3" />
        <origin xyz=" .2  .01  0" />
        <inertia
          ixx=" 0"
          ixy=" 0"
          ixz=" 0"
          iyy=" 0"
          iyz=" 0"
          izz=" 0"
        />
      </inertial>
    </link>

    <link name="${prefix}J5_link">
      <visual>
        <origin xyz="0 0 0" rpy="0 0 0" />
        <geometry>
          <mesh
            filename="package://fanuc_lrmate_description/meshes/lrmate200id/visual/j5.dae"
          />
        </geometry>
      </visual>
      <collision>
        <origin xyz="0 0 0" rpy="0 0 0" />
        <geometry>
          <mesh
            filename="package://fanuc_lrmate_description/meshes/lrmate200id/collision/j5.stl"
            scale="0.001 0.001 0.001"
          />
        </geometry>
      </collision>
      <inertial>
        <mass value=" 2" />
        <origin xyz=" .04  0  0" />
        <inertia
          ixx=" 0"
          ixy=" 0"
          ixz=" 0"
          iyy=" 0"
          iyz=" 0"
          izz=" 0"
        />
      </inertial>
    </link>

    <link name="${prefix}J6_link">
      <visual>
        <origin xyz="0 0 0" rpy="0 0 0" />
        <geometry>
          <mesh
            filename="package://fanuc_lrmate_description/meshes/lrmate200id/visual/j6.dae"
          />
        </geometry>
      </visual>
      <collision>
        <origin xyz="0 0 0" rpy="0 0 0" />
        <geometry>
          <mesh
            filename="package://fanuc_lrmate_description/meshes/lrmate200id/collision/j6.stl"
            scale="0.001 0.001 0.001"
          />
        </geometry>
      </collision>
      <inertial>
        <mass value=" 0" />
        <origin xyz=" 0  0  0" />
        <inertia
          ixx=" 0"
          ixy=" 0"
          ixz=" 0"
          iyy=" 0"
          iyz=" 0"
          izz=" 0"
        />
      </inertial>
    </link>

    <!-- joints -->
    <joint name="${prefix}J1" type="revolute">
      <origin xyz=" 0  0  .33" rpy="0 0 0" />
      <parent link="${prefix}base_link" />
      <child link="${prefix}J1_link" />
      <axis xyz=" 0  0  1" />
      <limit
        lower="${j1_lower_limit}"
        upper="${j1_upper_limit}"
        effort="${j1_effort_limit}"
        velocity="${j1_velocity_limit}"
      />
    </joint>

    <joint name="${prefix}J2" type="revolute">
      <origin xyz=" .05  0  0" rpy="0 0 0" />
      <parent link="${prefix}J1_link" />
      <child link="${prefix}J2_link" />
      <axis xyz=" 0  1  0" />
      <limit
        lower="${j2_lower_limit}"
        upper="${j2_upper_limit}"
        effort="${j2_effort_limit}"
        velocity="${j2_velocity_limit}"
      />
    </joint>

    <joint name="${prefix}J3" type="revolute">
      <origin xyz=" 0  0  .33" rpy="0 0 0" />
      <parent link="${prefix}J2_link" />
      <child link="${prefix}J3_link" />
      <axis xyz=" 0 -1  0" />
      <limit
        lower="${j3_lower_limit}"
        upper="${j3_upper_limit}"
        effort="${j3_effort_limit}"
        velocity="${j3_velocity_limit}"
      />
    </joint>

    <joint name="${prefix}J4" type="revolute">
      <origin xyz=" 0  0  .035" rpy="0 0 0" />
      <parent link="${prefix}J3_link" />
      <child link="${prefix}J4_link" />
      <axis xyz="-1  0  0" />
      <limit
        lower="${j4_lower_limit}"
        upper="${j4_upper_limit}"
        effort="${j4_effort_limit}"
        velocity="${j4_velocity_limit}"
      />
    </joint>

    <joint name="${prefix}J5" type="revolute">
      <origin xyz=" .335  0  0" rpy="0 0 0" />
      <parent link="${prefix}J4_link" />
      <child link="${prefix}J5_link" />
      <axis xyz=" 0 -1  0" />
      <limit
        lower="${j5_lower_limit}"
        upper="${j5_upper_limit}"
        effort="${j5_effort_limit}"
        velocity="${j5_velocity_limit}"
      />
    </joint>

    <joint name="${prefix}J6" type="revolute">
      <origin xyz=" 0  0  0" rpy="0 0 0" />
      <parent link="${prefix}J5_link" />
      <child link="${prefix}J6_link" />
      <axis xyz="-1  0  0" />
      <limit
        lower="${j6_lower_limit}"
        upper="${j6_upper_limit}"
        effort="${j6_effort_limit}"
        velocity="${j6_velocity_limit}"
      />
    </joint>

    <!-- world coords -->
    <link name="${prefix}wbase" />
    <joint name="${prefix}base_link-wbase" type="fixed">
      <origin xyz=" 0  0  .33" rpy="0 0 0" />
      <parent link="${prefix}base_link" />
      <child link="${prefix}wbase" />
    </joint>

    <!-- flange coords -->
    <link name="${prefix}flange" />
    <joint name="${prefix}J6-flange" type="fixed">
      <origin xyz=" .08  0  0" rpy="0 0 0" />
      <parent link="${prefix}J6_link" />
      <child link="${prefix}flange" />
    </joint>

    <!-- Attach to parent -->
    <joint name="${prefix}base_joint" type="fixed">
      <xacro:insert_block name="origin" />
      <parent link="${parent}" />
      <child link="${prefix}base_link" />
    </joint>

    <!-- Attach child -->
    <joint name="${prefix}child_joint" type="fixed">
      <origin xyz="0 0 0" rpy="0 0 0" />
      <parent link="${prefix}flange" />
      <child link="${child}" />
    </joint>
  </xacro:macro>
</robot>
